Workbook

Sheet 字根表
A1: 助记词字根表
A3: 1 | B3: abandon | C3: 513 | D3: divorce | E3: 1025 | F3: length | G3: 1537 | H3: scale
A4: 2 | B4: ability | C4: 514 | D4: dizzy | E4: 1026 | F4: lens | G4: 1538 | H4: scan
A5: 3 | B5: able | C5: 515 | D5: doctor | E5: 1027 | F5: leopard | G5: 1539 | H5: scare
A6: 4 | B6: about | C6: 516 | D6: document | E6: 1028 | F6: lesson | G6: 1540 | H6: scatter
A7: 5 | B7: above | C7: 517 | D7: dog | E7: 1029 | F7: letter | G7: 1541 | H7: scene
A8: 6 | B8: absent | C8: 518 | D8: doll | E8: 1030 | F8: level | G8: 1542 | H8: scheme
A9: 7 | B9: absorb | C9: 519 | D9: dolphin | E9: 1031 | F9: liar | G9: 1543 | H9: school
A10: 8 | B10: abstract | C10: 520 | D10: domain | E10: 1032 | F10: liberty | G10: 1544 | H10: science
A11: 9 | B11: absurd | C11: 521 | D11: donate | E11: 1033 | F11: library | G11: 1545 | H11: scissors
A12: 10 | B12: abuse | C12: 522 | D12: donkey | E12: 1034 | F12: license | G12: 1546 | H12: scorpion
A13: 11 | B13: access | C13: 523 | D13: donor | E13: 1035 | F13: life | G13: 1547 | H13: scout
A14: 12 | B14: accident | C14: 524 | D14: door | E14: 1036 | F14: lift | G14: 1548 | H14: scrap
... A148: 146 | B148: banana | C148: 658 | D148: fall | E148: 1170 | F148: mutual | G148: 1682 | H148: split
A149: 147 | B149: banner | C149: 659 | D149: FALSE | E149: 1171 | F149: myself | G149: 1683 | H149: spoil
A150: 148 | B150: bar | C150: 660 | D150: fame | E150: 1172 | F150: mystery | G150: 1684 | H150: sponsor
A151: 149 | B151: barely | C151: 661 | D151: family | E151: 1173 | F151: myth | G151: 1685 | H151: spoon
A152: 150 | B152: bargain | C152: 662 | D152: famous | E152: 1174 | F152: naive | G152: 1686 | H152: sport
A153: 151 | B153: barrel | C153: 663 | D153: fan | E153: 1175 | F153: name | G153: 1687 | H153: spot
A154: 152 | B154: base | C154: 664 | D154: fancy | E154: 1176 | F154: napkin | G154: 1688 | H154: spray
A155: 153 | B155: basic | C155: 665 | D155: fantasy | E155: 1177 | F155: narrow | G155: 1689 | H155: spread
A156: 154 | B156: basket | C156: 666 | D156: farm | E156: 1178 | F156: nasty | G156: 1690 | H156: spring
A157: 155 | B157: battle | C157: 667 | D157: fashion | E157: 1179 | F157: nation | G157: 1691 | H157: spy
A158: 156 | B158: beach | C158: 668 | D158: fat | E158: 1180 | F158: nature | G158: 1692 | H158: square
A159: 157 | B159: bean | C159: 669 | D159: fatal | E159: 1181 | F159: near | G159: 1693 | H159: squeeze
A160: 158 | B160: beauty | C160: 670 | D160: father | E160: 1182 | F160: neck | G160: 1694 | H160: squirrel
A161: 159 | B161: because | C161: 671 | D161: fatigue | E161: 1183 | F161: need | G161: 1695 | H161: stable
... A332: 330 | B332: circle | C332: 842 | D332: hard | E332: 1354 | F332: powder | G332: 1866 | H332: truck
A333: 331 | B333: citizen | C333: 843 | D333: harsh | E333: 1355 | F333: power | G333: 1867 | H333: TRUE
A334: 332 | B334: city | C334: 844 | D334: harvest | E334: 1356 | F334: practice | G334: 1868 | H334: truly
A335: 333 | B335: civil | C335: 845 | D335: hat | E335: 1357 | F335: praise | G335: 1869 | H335: trumpet
A336: 334 | B336: claim | C336: 846 | D336: have | E336: 1358 | F336: predict | G336: 1870 | H336: trust
A337: 335 | B337: clap | C337: 847 | D337: hawk | E337: 1359 | F337: prefer | G337: 1871 | H337: truth
A338: 336 | B338: clarify | C338: 848 | D338: hazard | E338: 1360 | F338: prepare | G338: 1872 | H338: try
A339: 337 | B339: claw | C339: 849 | D339: head | E339: 1361 | F339: present | G339: 1873 | H339: tube
A340: 338 | B340: clay | C340: 850 | D340: health | E340: 1362 | F340: pretty | G340: 1874 | H340: tuition
A341: 339 | B341: clean | C341: 851 | D341: heart | E341: 1363 | F341: prevent | G341: 1875 | H341: tumble
A342: 340 | B342: clerk | C342: 852 | D342: heavy | E342: 1364 | F342: price | G342: 1876 | H342: tuna
A343: 341 | B343: clever | C343: 853 | D343: hedgehog | E343: 1365 | F343: pride | G343: 1877 | H343: tunnel
A344: 342 | B344: click | C344: 854 | D344: height | E344: 1366 | F344: primary | G344: 1878 | H344: turkey
...

Sheet 字根表2
A1: 助记词字根表
A3: 1 | B3: abandon | C3: 257 | D3: cactus | E3: 513 | F3: divorce | G3: 769 | H3: gas | I3: 1025 | J3: length | K3: 1281 | L3: parade | M3: 1537 | N3: scale | O3: 1793 | P3: theme
A4: 2 | B4: ability | C4: 258 | D4: cage | E4: 514 | F4: dizzy | G4: 770 | H4: gasp | I4: 1026 | J4: lens | K4: 1282 | L4: parent | M4: 1538 | N4: scan | O4: 1794 | P4: then
A5: 3 | B5: able | C5: 259 | D5: cake | E5: 515 | F5: doctor | G5: 771 | H5: gate | I5: 1027 | J5: leopard | K5: 1283 | L5: park | M5: 1539 | N5: scare | O5: 1795 | P5: theory
A6: 4 | B6: about | C6: 260 | D6: call | E6: 516 | F6: document | G6: 772 | H6: gather | I6: 1028 | J6: lesson | K6: 1284 | L6: parrot | M6: 1540 | N6: scatter | O6: 1796 | P6: there
A7: 5 | B7: above | C7: 261 | D7: calm | E7: 517 | F7: dog | G7: 773 | H7: gauge | I7: 1029 | J7: letter | K7: 1285 | L7: party | M7: 1541 | N7: scene | O7: 1797 | P7: they
A8: 6 | B8: absent | C8: 262 | D8: camera | E8: 518 | F8: doll | G8: 774 | H8: gaze | I8: 1030 | J8: level | K8: 1286 | L8: pass | M8: 1542 | N8: scheme | O8: 1798 | P8: thing
A9: 7 | B9: absorb | C9: 263 | D9: camp | E9: 519 | F9: dolphin | G9: 775 | H9: general | I9: 1031 | J9: liar | K9: 1287 | L9: patch | M9: 1543 | N9: school | O9: 1799 | P9: this
A10: 8 | B10: abstract | C10: 264 | D10: can | E10: 520 | F10: domain | G10: 776 | H10: genius | I10: 1032 | J10: liberty | K10: 1288 | L10: path | M10: 1544 | N10: science | O10: 1800 | P10: thought
A11: 9 | B11: absurd | C11: 265 | D11: canal | E11: 521 | F11: donate | G11: 777 | H11: genre | I11: 1033 | J11: library | K11: 1289 | L11: patient | M11: 1545 | N11: scissors | O11: 1801 | P11: three
A12: 10 | B12: abuse | C12: 266 | D12: cancel | E12: 522 | F12: donkey | G12: 778 | H12: gentle | I12: 1034 | J12: license | K12: 1290 | L12: patrol | M12: 1546 | N12: scorpion | O12: 1802 | P12: thrive
A13: 11 | B13: access | C13: 267 | D13: candy | E13: 523 | F13: donor | G13: 779 | H13: genuine | I13: 1035 | J13: life | K13: 1291 | L13: pattern | M13: 1547 | N13: scout | O13: 1803 | P13: throw
A14: 12 | B14: accident | C14: 268 | D14: cannon | E14: 524 | F14: door | G14: 780 | H14: gesture | I14: 1036 | J14: lift | K14: 1292 | L14: pause | M14: 1548 | N14: scrap | O14: 1804 | P14: thumb
... A76: 74 | B76: ankle | C76: 330 | D76: circle | E76: 586 | F76: empty | G76: 842 | H76: hard | I76: 1098 | J76: matrix | K76: 1354 | L76: powder | M76: 1610 | N76: since | O76: 1866 | P76: truck
A77: 75 | B77: announce | C77: 331 | D77: citizen | E77: 587 | F77: enable | G77: 843 | H77: harsh | I77: 1099 | J77: matter | K77: 1355 | L77: power | M77: 1611 | N77: sing | O77: 1867 | P77: TRUE
A78: 76 | B78: annual | C78: 332 | D78: city | E78: 588 | F78: enact | G78: 844 | H78: harvest | I78: 1100 | J78: maximum | K78: 1356 | L78: practice | M78: 1612 | N78: siren | O78: 1868 | P78: truly
A79: 77 | B79: another | C79: 333 | D79: civil | E79: 589 | F79: end | G79: 845 | H79: hat | I79: 1101 | J79: maze | K79: 1357 | L79: praise | M79: 1613 | N79: sister | O79: 1869 | P79: trumpet
A80: 78 | B80: answer | C80: 334 | D80: claim | E80: 590 | F80: endless | G80: 846 | H80: have | I80: 1102 | J80: meadow | K80: 1358 | L80: predict | M80: 1614 | N80: situate | O80: 1870 | P80: trust
A81: 79 | B81: antenna | C81: 335 | D81: clap | E81: 591 | F81: endorse | G81: 847 | H81: hawk | I81: 1103 | J81: mean | K81: 1359 | L81: prefer | M81: 1615 | N81: six | O81: 1871 | P81: truth
A82: 80 | B82: antique | C82: 336 | D82: clarify | E82: 592 | F82: enemy | G82: 848 | H82: hazard | I82: 1104 | J82: measure | K82: 1360 | L82: prepare | M82: 1616 | N82: size | O82: 1872 | P82: try
A83: 81 | B83: anxiety | C83: 337 | D83: claw | E83: 593 | F83: energy | G83: 849 | H83: head | I83: 1105 | J83: meat | K83: 1361 | L83: present | M83: 1617 | N83: skate | O83: 1873 | P83: tube
A84: 82 | B84: any | C84: 338 | D84: clay | E84: 594 | F84: enforce | G84: 850 | H84: health | I84: 1106 | J84: mechanic | K84: 1362 | L84: pretty | M84: 1618 | N84: sketch | O84: 1874 | P84: tuition
A85: 83 | B85: apart | C85: 339 | D85: clean | E85: 595 | F85: engage | G85: 851 | H85: heart | I85: 1107 | J85: medal | K85: 1363 | L85: prevent | M85: 1619 | N85: ski | O85: 1875 | P85: tumble
A86: 84 | B86: apology | C86: 340 | D86: clerk | E86: 596 | F86: engine | G86: 852 | H86: heavy | I86: 1108 | J86: media | K86: 1364 | L86: price | M86: 1620 | N86: skill | O86: 1876 | P86: tuna
A87: 85 | B87: appear | C87: 341 | D87: clever | E87: 597 | F87: enhance | G87: 853 | H87: hedgehog | I87: 1109 | J87: melody | K87: 1365 | L87: pride | M87: 1621 | N87: skin | O87: 1877 | P87: tunnel
A88: 86 | B88: apple | C88: 342 | D88: click | E88: 598 | F88: enjoy | G88: 854 | H88: height | I88: 1110 | J88: melt | K88: 1366 | L88: primary | M88: 1622 | N88: skirt | O88: 1878 | P88: turkey
A89: 87 | B89: approve | C89: 343 | D89: client | E89: 599 | F89: enlist | G89: 855 | H89: hello | I89: 1111 | J89: member | K89: 1367 | L89: print | M89: 1623 | N89: skull | O89: 1879 | P89: turn
... A148: 146 | B148: banana | C148: 402 | D148: cram | E148: 658 | F148: fall | G148: 914 | H148: impulse | I148: 1170 | J148: mutual | K148: 1426 | L148: rate | M148: 1682 | N148: split | O148: 1938 | P148: vendor
A149: 147 | B149: banner | C149: 403 | D149: crane | E149: 659 | F149: FALSE | G149: 915 | H149: inch | I149: 1171 | J149: myself | K149: 1427 | L149: rather | M149: 1683 | N149: spoil | O149: 1939 | P149: venture
A150: 148 | B150: bar | C150: 404 | D150: crash | E150: 660 | F150: fame | G150: 916 | H150: include | I150: 1172 | J150: mystery | K150: 1428 | L150: raven | M150: 1684 | N150: sponsor | O150: 1940 | P150: venue
A151: 149 | B151: barely | C151: 405 | D151: crater | E151: 661 | F151: family | G151: 917 | H151: income | I151: 1173 | J151: myth | K151: 1429 | L151: raw | M151: 1685 | N151: spoon | O151: 1941 | P151: verb
A152: 150 | B152: bargain | C152: 406 | D152: crawl | E152: 662 | F152: famous | G152: 918 | H152: increase | I152: 1174 | J152: naive | K152: 1430 | L152: razor | M152: 1686 | N152: sport | O152: 1942 | P152: verify
A153: 151 | B153: barrel | C153: 407 | D153: crazy | E153: 663 | F153: fan | G153: 919 | H153: index | I153: 1175 | J153: name | K153: 1431 | L153: ready | M153: 1687 | N153: spot | O153: 1943 | P153: version
A154: 152 | B154: base | C154: 408 | D154: cream | E154: 664 | F154: fancy | G154: 920 | H154: indicate | I154: 1176 | J154: napkin | K154: 1432 | L154: real | M154: 1688 | N154: spray | O154: 1944 | P154: very
A155: 153 | B155: basic | C155: 409 | D155: credit | E155: 665 | F155: fantasy | G155: 921 | H155: indoor | I155: 1177 | J155: narrow | K155: 1433 | L155: reason | M155: 1689 | N155: spread | O155: 1945 | P155: vessel
A156: 154 | B156: basket | C156: 410 | D156: creek | E156: 666 | F156: farm | G156: 922 | H156: industry | I156: 1178 | J156: nasty | K156: 1434 | L156: rebel | M156: 1690 | N156: spring | O156: 1946 | P156: veteran
A157: 155 | B157: battle | C157: 411 | D157: crew | E157: 667 | F157: fashion | G157: 923 | H157: infant | I157: 1179 | J157: nation | K157: 1435 | L157: rebuild | M157: 1691 | N157: spy | O157: 1947 | P157: viable
A158: 156 | B158: beach | C158: 412 | D158: cricket | E158: 668 | F158: fat | G158: 924 | H158: inflict | I158: 1180 | J158: nature | K158: 1436 | L158: recall | M158: 1692 | N158: square | O158: 1948 | P158: vibrant
A159: 157 | B159: bean | C159: 413 | D159: crime | E159: 669 | F159: fatal | G159: 925 | H159: inform | I159: 1181 | J159: near | K159: 1437 | L159: receive | M159: 1693 | N159: squeeze | O159: 1949 | P159: vicious
A160: 158 | B160: beauty | C160: 414 | D160: crisp | E160: 670 | F160: father | G160: 926 | H160: inhale | I160: 1182 | J160: neck | K160: 1438 | L160: recipe | M160: 1694 | N160: squirrel | O160: 1950 | P160: victory
...

Sheet 字根顺序表
A1: 编号 | B1: 名称
A2: 1 | B2: abandon
A3: 2 | B3: ability
A4: 3 | B4: able
A5: 4 | B5: about
A6: 5 | B6: above
A7: 6 | B7: absent
A8: 7 | B8: absorb
A9: 8 | B9: abstract
A10: 9 | B10: absurd
A11: 10 | B11: abuse
A12: 11 | B12: access
A13: 12 | B13: accident
... A659: 658 | B659: fall
A660: 659 | B660: FALSE
A661: 660 | B661: fame
A662: 661 | B662: family
A663: 662 | B663: famous
A664: 663 | B664: fan
A665: 664 | B665: fancy
A666: 665 | B666: fantasy
A667: 666 | B667: farm
A668: 667 | B668: fashion
A669: 668 | B669: fat
A670: 669 | B670: fatal
A671: 670 | B671: father
A672: 671 | B672: fatigue
... A1867: 1866 | B1867: truck
A1868: 1867 | B1868: TRUE
A1869: 1868 | B1869: truly
A1870: 1869 | B1870: trumpet
A1871: 1870 | B1871: trust
A1872: 1871 | B1872: truth
A1873: 1872 | B1873: try
A1874: 1873 | B1874: tube
A1875: 1874 | B1875: tuition
A1876: 1875 | B1876: tumble
A1877: 1876 | B1877: tuna
A1878: 1877 | B1878: tunnel
A1879: 1878 | B1879: turkey
...

Sheet 工程样本
B1: 单词查找表（一） | F1: 单词查找表（二） | J1: 单词查找表（三） | N1: 单词查找表（四）
B2: 顺序号 | C2: 编号 | D2: 名称 | F2: 顺序号 | G2: 编号 | H2: 名称 | J2: 顺序号 | K2: 名称 | L2: 编号 | N2: 顺序号 | O2: 编号 | P2: 名称
B3: 1 | C3: 1 | D3: =_xlfn.XLOOKUP(C3,字根顺序表!$A$1:$A$2049,字根顺序表!$B$1:$B$2049) -> abandon | F3: 1 | G3: =C3+0 -> 1 | H3: =_xlfn.XLOOKUP(G3,字根顺序表!$A$1:$A$2049,字根顺序表!$B$1:$B$2049,"test") -> abandon | J3: 1 | K3: gadget | L3: =_xlfn.XLOOKUP(K3,字根顺序表!$B$1:$B$2049,字根顺序表!$A$1:$A$2049,"test") -> 758 | N3: 1 | O3: =L3 -> 758 | P3: =_xlfn.XLOOKUP(O3,字根顺序表!$A$1:$A$2049,字根顺序表!$B$1:$B$2049,"test") -> gadget
B4: 2 | C4: 2 | D4: =_xlfn.XLOOKUP(C4,字根顺序表!$A$1:$A$2049,字根顺序表!$B$1:$B$2049) -> ability | F4: 2 | G4: =C4+0 -> 2 | H4: =_xlfn.XLOOKUP(G4,字根顺序表!$A$1:$A$2049,字根顺序表!$B$1:$B$2049,"test") -> ability | J4: 2 | K4: gadget | L4: =_xlfn.XLOOKUP(K4,字根顺序表!$B$1:$B$2049,字根顺序表!$A$1:$A$2049,"test") -> 758 | N4: 2 | O4: =L4 -> 758 | P4: =_xlfn.XLOOKUP(O4,字根顺序表!$A$1:$A$2049,字根顺序表!$B$1:$B$2049,"test") -> gadget
B5: 3 | C5: 1280 | D5: =_xlfn.XLOOKUP(C5,字根顺序表!$A$1:$A$2049,字根顺序表!$B$1:$B$2049) -> paper | F5: 3 | G5: =C5+0 -> 1280 | H5: =_xlfn.XLOOKUP(G5,字根顺序表!$A$1:$A$2049,字根顺序表!$B$1:$B$2049,"test") -> paper | J5: 3 | K5: gauge | L5: =_xlfn.XLOOKUP(K5,字根顺序表!$B$1:$B$2049,字根顺序表!$A$1:$A$2049,"test") -> 773 | N5: 3 | O5: =L5 -> 773 | P5: =_xlfn.XLOOKUP(O5,字根顺序表!$A$1:$A$2049,字根顺序表!$B$1:$B$2049,"test") -> gauge
B6: 4 | C6: 1862 | D6: =_xlfn.XLOOKUP(C6,字根顺序表!$A$1:$A$2049,字根顺序表!$B$1:$B$2049) -> trim | F6: 4 | G6: =C6+0 -> 1862 | H6: =_xlfn.XLOOKUP(G6,字根顺序表!$A$1:$A$2049,字根顺序表!$B$1:$B$2049,"test") -> trim | J6: 4 | K6: raw | L6: =_xlfn.XLOOKUP(K6,字根顺序表!$B$1:$B$2049,字根顺序表!$A$1:$A$2049,"test") -> 1429 | N6: 4 | O6: =L6 -> 1429 | P6: =_xlfn.XLOOKUP(O6,字根顺序表!$A$1:$A$2049,字根顺序表!$B$1:$B$2049,"test") -> raw
B7: 5 | C7: 1294 | D7: =_xlfn.XLOOKUP(C7,字根顺序表!$A$1:$A$2049,字根顺序表!$B$1:$B$2049) -> payment | F7: 5 | G7: =C7+0 -> 1294 | H7: =_xlfn.XLOOKUP(G7,字根顺序表!$A$1:$A$2049,字根顺序表!$B$1:$B$2049,"test") -> payment | J7: 5 | K7: clock | L7: =_xlfn.XLOOKUP(K7,字根顺序表!$B$1:$B$2049,字根顺序表!$A$1:$A$2049,"test") -> 348 | N7: 5 | O7: =L7 -> 348 | P7: =_xlfn.XLOOKUP(O7,字根顺序表!$A$1:$A$2049,字根顺序表!$B$1:$B$2049,"test") -> clock
B8: 6 | C8: 1990 | D8: =_xlfn.XLOOKUP(C8,字根顺序表!$A$1:$A$2049,字根顺序表!$B$1:$B$2049) -> weather | F8: 6 | G8: =C8+0 -> 1990 | H8: =_xlfn.XLOOKUP(G8,字根顺序表!$A$1:$A$2049,字根顺序表!$B$1:$B$2049,"test") -> weather | J8: 6 | K8: letter | L8: =_xlfn.XLOOKUP(K8,字根顺序表!$B$1:$B$2049,字根顺序表!$A$1:$A$2049,"test") -> 1029 | N8: 6 | O8: =L8 -> 1029 | P8: =_xlfn.XLOOKUP(O8,字根顺序表!$A$1:$A$2049,字根顺序表!$B$1:$B$2049,"test") -> letter
B9: 7 | C9: 1335 | D9: =_xlfn.XLOOKUP(C9,字根顺序表!$A$1:$A$2049,字根顺序表!$B$1:$B$2049) -> plug | F9: 7 | G9: =C9+0 -> 1335 | H9: =_xlfn.XLOOKUP(G9,字根顺序表!$A$1:$A$2049,字根顺序表!$B$1:$B$2049,"test") -> plug | J9: 7 | K9: firm | L9: =_xlfn.XLOOKUP(K9,字根顺序表!$B$1:$B$2049,字根顺序表!$A$1:$A$2049,"test") -> 699 | N9: 7 | O9: =L9 -> 699 | P9: =_xlfn.XLOOKUP(O9,字根顺序表!$A$1:$A$2049,字根顺序表!$B$1:$B$2049,"test") -> firm
B10: 8 | C10: 973 | D10: =_xlfn.XLOOKUP(C10,字根顺序表!$A$1:$A$2049,字根顺序表!$B$1:$B$2049) -> kangaroo | F10: 8 | G10: =C10+0 -> 973 | H10: =_xlfn.XLOOKUP(G10,字根顺序表!$A$1:$A$2049,字根顺序表!$B$1:$B$2049,"test") -> kangaroo | J10: 8 | K10: ten | L10: =_xlfn.XLOOKUP(K10,字根顺序表!$B$1:$B$2049,字根顺序表!$A$1:$A$2049,"test") -> 1784 | N10: 8 | O10: =L10 -> 1784 | P10: =_xlfn.XLOOKUP(O10,字根顺序表!$A$1:$A$2049,字根顺序表!$B$1:$B$2049,"test") -> ten
B11: 9 | C11: 1733 | D11: =_xlfn.XLOOKUP(C11,字根顺序表!$A$1:$A$2049,字根顺序表!$B$1:$B$2049) -> sudden | F11: 9 | G11: =C11+0 -> 1733 | H11: =_xlfn.XLOOKUP(G11,字根顺序表!$A$1:$A$2049,字根顺序表!$B$1:$B$2049,"test") -> sudden | J11: 9 | K11: snap | L11: =_xlfn.XLOOKUP(K11,字根顺序表!$B$1:$B$2049,字根顺序表!$A$1:$A$2049,"test") -> 1643 | N11: 9 | O11: =L11 -> 1643 | P11: =_xlfn.XLOOKUP(O11,字根顺序表!$A$1:$A$2049,字根顺序表!$B$1:$B$2049,"test") -> snap
B12: 10 | C12: 1060 | D12: =_xlfn.XLOOKUP(C12,字根顺序表!$A$1:$A$2049,字根顺序表!$B$1:$B$2049) -> love | F12: 10 | G12: =C12+0 -> 1060 | H12: =_xlfn.XLOOKUP(G12,字根顺序表!$A$1:$A$2049,字根顺序表!$B$1:$B$2049,"test") -> love | J12: 10 | K12: absorb | L12: =_xlfn.XLOOKUP(K12,字根顺序表!$B$1:$B$2049,字根顺序表!$A$1:$A$2049,"test") -> 7 | N12: 10 | O12: =L12 -> 7 | P12: =_xlfn.XLOOKUP(O12,字根顺序表!$A$1:$A$2049,字根顺序表!$B$1:$B$2049,"test") -> absorb
B13: 11 | C13: 2020 | D13: =_xlfn.XLOOKUP(C13,字根顺序表!$A$1:$A$2049,字根顺序表!$B$1:$B$2049) -> wise | F13: 11 | G13: =C13+0 -> 2020 | H13: =_xlfn.XLOOKUP(G13,字根顺序表!$A$1:$A$2049,字根顺序表!$B$1:$B$2049,"test") -> wise | J13: 11 | K13: oxygen | L13: =_xlfn.XLOOKUP(K13,字根顺序表!$B$1:$B$2049,字根顺序表!$A$1:$A$2049,"test") -> 1267 | N13: 11 | O13: =L13 -> 1267 | P13: =_xlfn.XLOOKUP(O13,字根顺序表!$A$1:$A$2049,字根顺序表!$B$1:$B$2049,"test") -> oxygen
B14: 12 | C14: 1209 | D14: =_xlfn.XLOOKUP(C14,字根顺序表!$A$1:$A$2049,字根顺序表!$B$1:$B$2049) -> novel | F14: 12 | G14: =C14+0 -> 1209 | H14: =_xlfn.XLOOKUP(G14,字根顺序表!$A$1:$A$2049,字根顺序表!$B$1:$B$2049,"test") -> novel | J14: 12 | K14: bind | L14: =_xlfn.XLOOKUP(K14,字根顺序表!$B$1:$B$2049,字根顺序表!$A$1:$A$2049,"test") -> 179 | N14: 12 | O14: =L14 -> 179 | P14: =_xlfn.XLOOKUP(O14,字根顺序表!$A$1:$A$2049,字根顺序表!$B$1:$B$2049,"test") -> bind
... B16: 14 | C16: 812 | D16: =_xlfn.XLOOKUP(C16,字根顺序表!$A$1:$A$2049,字根顺序表!$B$1:$B$2049) -> grace | F16: 14 | G16: =C16+0 -> 812 | H16: =_xlfn.XLOOKUP(G16,字根顺序表!$A$1:$A$2049,字根顺序表!$B$1:$B$2049,"test") -> grace | J16: 14 | K16: grace | L16: =_xlfn.XLOOKUP(K16,字根顺序表!$B$1:$B$2049,字根顺序表!$A$1:$A$2049,"test") -> 812 | N16: 14 | O16: =L16 -> 812 | P16: =_xlfn.XLOOKUP(O16,字根顺序表!$A$1:$A$2049,字根顺序表!$B$1:$B$2049,"test") -> grace
B17: 15 | C17: 12 | D17: =_xlfn.XLOOKUP(C17,字根顺序表!$A$1:$A$2049,字根顺序表!$B$1:$B$2049) -> accident | F17: 15 | G17: =C17+0 -> 12 | H17: =_xlfn.XLOOKUP(G17,字根顺序表!$A$1:$A$2049,字根顺序表!$B$1:$B$2049,"test") -> accident | J17: 15 | K17: accident | L17: =_xlfn.XLOOKUP(K17,字根顺序表!$B$1:$B$2049,字根顺序表!$A$1:$A$2049,"test") -> 12 | N17: 15 | O17: 12 | P17: =_xlfn.XLOOKUP(O17,字根顺序表!$A$1:$A$2049,字根顺序表!$B$1:$B$2049,"test") -> accident
